Workbook

Sheet Hướng dẫn
A1: Checklist rà soát BRS theo ISO/IEC/IEEE 29148:2018
A2: Tài liệu được rà soát | B2: requirements/BRD_IP_Camera_Web.md – phiên bản 0.3
A3: Ngày rà soát | B3: 21/10/2026
A4: Người rà soát | B4: Business Analyst (cần điền tên)
A6: Cách dùng
A7: 1 | B7: Mở sheet "Checklist". Với mỗi dòng, đọc câu hỏi và mục BRS tương ứng.
A8: 2 | B8: Chọn Trạng thái từ danh sách thả xuống; ghi bằng chứng và hành động cần làm.
A9: 3 | B9: Chỉ sửa các ô nền vàng nhạt (Trạng thái, Bằng chứng, Hành động, Người phụ trách, Hạn). Các cột khác là nội dung chuẩn của checklist.
A10: 4 | B10: Sheet "Tổng hợp" tự tính theo công thức, không cần nhập tay.
A11: 5 | B11: Các dòng đã được điền sẵn kết quả rà soát BRS v0.3 và có thể dùng làm mẫu cho các lần rà soát sau.
A13: Ý nghĩa trạng thái
A14: Đạt | B14: Tài liệu đáp ứng đầy đủ câu hỏi, có bằng chứng ở mục BRS đã ghi.
A15: Một phần | B15: Có nội dung nhưng thiếu hoặc chưa được xác nhận; cần hành động bổ sung.
A16: Không đạt | B16: Chưa có nội dung hoặc vi phạm tiêu chí.
A17: Chưa kiểm tra | B17: Cần thêm người hoặc thông tin mới đánh giá được (ví dụ cần stakeholder review).
A18: N/A | B18: Không áp dụng cho tài liệu này; ghi lý do ở cột Bằng chứng. Không tính vào tỷ lệ đạt.
A20: Nguồn tiêu chí
A21: ISO/IEC/IEEE 29148:2018 | B21: §5.2.4 cấu trúc phát biểu yêu cầu; §5.2.5 đặc tính từng yêu cầu; §5.2.6 đặc tính bộ yêu cầu; §5.2.7 tiêu chí ngôn ngữ; §5.2.8 thuộc tính yêu cầu; §9.3 nội dung BRS.
A22: Checklist gốc | B22: github.com/minhtrantrong/SDLC-Prompt-Checklist – analysis/BRD_IEEE_29148_Checklist.xlsx (các mục ghi "Checklist gốc" được giữ lại từ đây).
A23: Lưu ý | B23: Số mục và tên mục tiêu chuẩn được ghi theo cấu trúc của 29148:2018; nên đối chiếu với bản tiêu chuẩn chính thức trước khi dùng cho đánh giá tuân thủ chính thức.

Sheet Tổng hợp
A1: Tổng hợp kết quả rà soát
A2: Tự tính từ sheet Checklist. Tỷ lệ đạt = Đạt / (Tổng − N/A).
A4: Nhóm | B4: Đạt | C4: Một phần | D4: Không đạt | E4: Chưa kiểm tra | F4: N/A | G4: Tổng | H4: Tỷ lệ đạt
A5: A. Cấu trúc tài liệu BRS | B5: =COUNTIFS(Checklist!$B$2:$B$60,$A5,Checklist!$G$2:$G$60,B$4) | C5: =COUNTIFS(Checklist!$B$2:$B$60,$A5,Checklist!$G$2:$G$60,C$4) | D5: =COUNTIFS(Checklist!$B$2:$B$60,$A5,Checklist!$G$2:$G$60,D$4) | E5: =COUNTIFS(Checklist!$B$2:$B$60,$A5,Checklist!$G$2:$G$60,E$4) | F5: =COUNTIFS(Checklist!$B$2:$B$60,$A5,Checklist!$G$2:$G$60,F$4) | G5: =COUNTIF(Checklist!$B$2:$B$60,$A5) | H5: =IF(G5-F5=0,"-",B5/(G5-F5))
A6: B. Yêu cầu quản lý nghiệp vụ | B6: =COUNTIFS(Checklist!$B$2:$B$60,$A6,Checklist!$G$2:$G$60,B$4) | C6: =COUNTIFS(Checklist!$B$2:$B$60,$A6,Checklist!$G$2:$G$60,C$4) | D6: =COUNTIFS(Checklist!$B$2:$B$60,$A6,Checklist!$G$2:$G$60,D$4) | E6: =COUNTIFS(Checklist!$B$2:$B$60,$A6,Checklist!$G$2:$G$60,E$4) | F6: =COUNTIFS(Checklist!$B$2:$B$60,$A6,Checklist!$G$2:$G$60,F$4) | G6: =COUNTIF(Checklist!$B$2:$B$60,$A6) | H6: =IF(G6-F6=0,"-",B6/(G6-F6))
A7: C. Yêu cầu vận hành nghiệp vụ | B7: =COUNTIFS(Checklist!$B$2:$B$60,$A7,Checklist!$G$2:$G$60,B$4) | C7: =COUNTIFS(Checklist!$B$2:$B$60,$A7,Checklist!$G$2:$G$60,C$4) | D7: =COUNTIFS(Checklist!$B$2:$B$60,$A7,Checklist!$G$2:$G$60,D$4) | E7: =COUNTIFS(Checklist!$B$2:$B$60,$A7,Checklist!$G$2:$G$60,E$4) | F7: =COUNTIFS(Checklist!$B$2:$B$60,$A7,Checklist!$G$2:$G$60,F$4) | G7: =COUNTIF(Checklist!$B$2:$B$60,$A7) | H7: =IF(G7-F7=0,"-",B7/(G7-F7))
A8: D. Khái niệm vận hành và vòng đời | B8: =COUNTIFS(Checklist!$B$2:$B$60,$A8,Checklist!$G$2:$G$60,B$4) | C8: =COUNTIFS(Checklist!$B$2:$B$60,$A8,Checklist!$G$2:$G$60,C$4) | D8: =COUNTIFS(Checklist!$B$2:$B$60,$A8,Checklist!$G$2:$G$60,D$4) | E8: =COUNTIFS(Checklist!$B$2:$B$60,$A8,Checklist!$G$2:$G$60,E$4) | F8: =COUNTIFS(Checklist!$B$2:$B$60,$A8,Checklist!$G$2:$G$60,F$4) | G8: =COUNTIF(Checklist!$B$2:$B$60,$A8) | H8: =IF(G8-F8=0,"-",B8/(G8-F8))
A9: E. Ràng buộc, giả định, phụ thuộc, rủi ro | B9: =COUNTIFS(Checklist!$B$2:$B$60,$A9,Checklist!$G$2:$G$60,B$4) | C9: =COUNTIFS(Checklist!$B$2:$B$60,$A9,Checklist!$G$2:$G$60,C$4) | D9: =COUNTIFS(Checklist!$B$2:$B$60,$A9,Checklist!$G$2:$G$60,D$4) | E9: =COUNTIFS(Checklist!$B$2:$B$60,$A9,Checklist!$G$2:$G$60,E$4) | F9: =COUNTIFS(Checklist!$B$2:$B$60,$A9,Checklist!$G$2:$G$60,F$4) | G9: =COUNTIF(Checklist!$B$2:$B$60,$A9) | H9: =IF(G9-F9=0,"-",B9/(G9-F9))
A10: F. Đặc tính từng yêu cầu | B10: =COUNTIFS(Checklist!$B$2:$B$60,$A10,Checklist!$G$2:$G$60,B$4) | C10: =COUNTIFS(Checklist!$B$2:$B$60,$A10,Checklist!$G$2:$G$60,C$4) | D10: =COUNTIFS(Checklist!$B$2:$B$60,$A10,Checklist!$G$2:$G$60,D$4) | E10: =COUNTIFS(Checklist!$B$2:$B$60,$A10,Checklist!$G$2:$G$60,E$4) | F10: =COUNTIFS(Checklist!$B$2:$B$60,$A10,Checklist!$G$2:$G$60,F$4) | G10: =COUNTIF(Checklist!$B$2:$B$60,$A10) | H10: =IF(G10-F10=0,"-",B10/(G10-F10))
A11: G. Ngôn ngữ yêu cầu | B11: =COUNTIFS(Checklist!$B$2:$B$60,$A11,Checklist!$G$2:$G$60,B$4) | C11: =COUNTIFS(Checklist!$B$2:$B$60,$A11,Checklist!$G$2:$G$60,C$4) | D11: =COUNTIFS(Checklist!$B$2:$B$60,$A11,Checklist!$G$2:$G$60,D$4) | E11: =COUNTIFS(Checklist!$B$2:$B$60,$A11,Checklist!$G$2:$G$60,E$4) | F11: =COUNTIFS(Checklist!$B$2:$B$60,$A11,Checklist!$G$2:$G$60,F$4) | G11: =COUNTIF(Checklist!$B$2:$B$60,$A11) | H11: =IF(G11-F11=0,"-",B11/(G11-F11))
A12: H. Thuộc tính yêu cầu | B12: =COUNTIFS(Checklist!$B$2:$B$60,$A12,Checklist!$G$2:$G$60,B$4) | C12: =COUNTIFS(Checklist!$B$2:$B$60,$A12,Checklist!$G$2:$G$60,C$4) | D12: =COUNTIFS(Checklist!$B$2:$B$60,$A12,Checklist!$G$2:$G$60,D$4) | E12: =COUNTIFS(Checklist!$B$2:$B$60,$A12,Checklist!$G$2:$G$60,E$4) | F12: =COUNTIFS(Checklist!$B$2:$B$60,$A12,Checklist!$G$2:$G$60,F$4) | G12: =COUNTIF(Checklist!$B$2:$B$60,$A12) | H12: =IF(G12-F12=0,"-",B12/(G12-F12))
A13: I. Đặc tính bộ yêu cầu | B13: =COUNTIFS(Checklist!$B$2:$B$60,$A13,Checklist!$G$2:$G$60,B$4) | C13: =COUNTIFS(Checklist!$B$2:$B$60,$A13,Checklist!$G$2:$G$60,C$4) | D13: =COUNTIFS(Checklist!$B$2:$B$60,$A13,Checklist!$G$2:$G$60,D$4) | E13: =COUNTIFS(Checklist!$B$2:$B$60,$A13,Checklist!$G$2:$G$60,E$4) | F13: =COUNTIFS(Checklist!$B$2:$B$60,$A13,Checklist!$G$2:$G$60,F$4) | G13: =COUNTIF(Checklist!$B$2:$B$60,$A13) | H13: =IF(G13-F13=0,"-",B13/(G13-F13))
A14: J. Tuân thủ và bảo mật | B14: =COUNTIFS(Checklist!$B$2:$B$60,$A14,Checklist!$G$2:$G$60,B$4) | C14: =COUNTIFS(Checklist!$B$2:$B$60,$A14,Checklist!$G$2:$G$60,C$4) | D14: =COUNTIFS(Checklist!$B$2:$B$60,$A14,Checklist!$G$2:$G$60,D$4) | E14: =COUNTIFS(Checklist!$B$2:$B$60,$A14,Checklist!$G$2:$G$60,E$4) | F14: =COUNTIFS(Checklist!$B$2:$B$60,$A14,Checklist!$G$2:$G$60,F$4) | G14: =COUNTIF(Checklist!$B$2:$B$60,$A14) | H14: =IF(G14-F14=0,"-",B14/(G14-F14))
A15: Tổng cộng | B15: =SUM(B5:B14) | C15: =SUM(C5:C14) | D15: =SUM(D5:D14) | E15: =SUM(E5:E14) | F15: =SUM(F5:F14) | G15: =SUM(G5:G14) | H15: =IF(G15-F15=0,"-",B15/(G15-F15))
A17: Kiểm tra: số dòng Checklist chưa chọn trạng thái | B17: =COUNTA(Checklist!$A$2:$A$60)-COUNTA(Checklist!$G$2:$G$60)

Sheet Checklist
A1: ID | B1: Nhóm | C1: Mục kiểm tra | D1: Câu hỏi kiểm tra | E1: Tham chiếu 29148 | F1: Mục trong BRS | G1: Trạng thái | H1: Bằng chứng / Ghi chú | I1: Hành động cần làm | J1: Người phụ trách | K1: Hạn
A2: A01 | B2: A. Cấu trúc tài liệu BRS | C2: Mục đích nghiệp vụ | D2: Tài liệu có nêu rõ lý do kinh doanh, vấn đề hoặc cơ hội dẫn đến dự án không? | E2: §9.3 Business purpose | F2: 1.1 | G2: Đạt | H2: Nêu vấn đề phân mảnh do nhiều phần mềm của từng hãng.
A3: A02 | B3: A. Cấu trúc tài liệu BRS | C3: Phạm vi nghiệp vụ | D3: Có liệt kê rõ phần trong phạm vi và ngoài phạm vi không? | E3: §9.3 Business scope | F3: 1.2 | G3: Đạt | H3: 9 mục in-scope, 6 mục out-of-scope.
A4: A03 | B4: A. Cấu trúc tài liệu BRS | C4: Tổng quan nghiệp vụ | D4: Có sơ đồ hoặc mô tả tổng quan hệ thống và các bên giao tiếp không? | E4: §9.3 Business overview | F4: 1.3 | G4: Đạt | H4: Sơ đồ Mermaid tổng quan.
A5: A04 | B5: A. Cấu trúc tài liệu BRS | C5: Định nghĩa và viết tắt | D5: Mọi thuật ngữ chuyên môn và viết tắt có được định nghĩa không? | E5: §9.3 Definitions; Appendix | F5: 1.4, 8.1 | G5: Đạt
A6: A05 | B6: A. Cấu trúc tài liệu BRS | C6: Stakeholder chính | D6: Đã xác định đầy đủ stakeholder nội bộ, bên ngoài và mối quan tâm của họ chưa? | E6: §9.3 Major stakeholders | F6: 1.5 | G6: Đạt | H6: Đã thêm người bị ghi hình (chủ thể dữ liệu).
A7: A06 | B7: A. Cấu trúc tài liệu BRS | C7: Tài liệu tham chiếu | D7: Có danh sách tài liệu, tiêu chuẩn, quy định được tham chiếu không? | E7: §9.3 References | F7: 2 | G7: Đạt | H7: REF-01 đến REF-05.
A8: A07 | B8: A. Cấu trúc tài liệu BRS | C8: Kiểm soát phiên bản và phê duyệt | D8: Có lịch sử phiên bản và danh sách người phê duyệt có tên không? | E8: §6 Information items (quản lý thông tin) | F8: Đầu tài liệu, 8.3 | G8: Một phần | H8: Có lịch sử phiên bản; bảng phê duyệt chưa có tên. | I8: Điền tên người phê duyệt.
A9: B01 | B9: B. Yêu cầu quản lý nghiệp vụ | C9: Môi trường nghiệp vụ | D9: Có mô tả vấn đề hiện tại và các yếu tố bên ngoài (pháp lý, thị trường, hạ tầng) không? | E9: §9.3 Business environment | F9: 3.1 | G9: Đạt | H9: P1–P5 và 3 yếu tố bên ngoài.
A10: B02 | B10: B. Yêu cầu quản lý nghiệp vụ | C10: Mục tiêu và KPI | D10: Mục tiêu có đo được, có giá trị mục tiêu, có thời hạn và có mức hiện tại (baseline) không? | E10: §9.3 Mission, goals and objectives | F10: 3.2 | G10: Một phần | H10: BO-04 "giảm 70% so với hiện tại" chưa có số hiện tại; các KPI chưa được Sponsor xác nhận. | I10: Đo baseline; Sponsor xác nhận KPI.
A11: B03 | B11: B. Yêu cầu quản lý nghiệp vụ | C11: Lợi ích tài chính / ROI | D11: Có ước tính chi phí, lợi ích, thời gian hoàn vốn không? | E11: Mở rộng ngoài 29148 (checklist gốc) | F11: 3.5 | G11: Một phần | H11: Có mục 3.5 Lợi ích và chi phí; chưa có số liệu chi phí và thời gian hoàn vốn. | I11: Bổ sung số liệu khi có quyết định OQ-02 và ngân sách.
A12: B04 | B12: B. Yêu cầu quản lý nghiệp vụ | C12: Mô hình nghiệp vụ | D12: Đã chọn mô hình kinh doanh/vận hành (nội bộ, SaaS…) chưa? | E12: §9.3 Business model | F12: 3.3 | G12: Đạt | H12: Đã chốt OQ-01: nội bộ trước, SaaS sau.
A13: B05 | B13: B. Yêu cầu quản lý nghiệp vụ | C13: Môi trường thông tin | D13: Có mô tả loại dữ liệu, nguồn, thời gian lưu, độ nhạy cảm và hệ thống trao đổi không? | E13: §9.3 Information environment | F13: 3.4 | G13: Đạt
A14: C01 | B14: C. Yêu cầu vận hành nghiệp vụ | C14: Quy trình hiện tại (As-Is) | D14: Quy trình hiện tại có được mô tả để làm bối cảnh cho thay đổi không? | E14: §9.3 Business processes | F14: 4.1 | G14: Đạt
A15: C02 | B15: C. Yêu cầu vận hành nghiệp vụ | C15: Quy trình mục tiêu (To-Be) | D15: Quy trình mới có được minh họa và chỉ ra điểm cải tiến so với hiện tại không? | E15: §9.3 Business processes | F15: 4.1 | G15: Đạt | H15: Có sơ đồ và bảng so sánh.
A16: C03 | B16: C. Yêu cầu vận hành nghiệp vụ | C16: Chính sách và quy tắc nghiệp vụ | D16: Các quy tắc nghiệp vụ có được tách riêng, đánh mã và viết rõ không? | E16: §9.3 Business operational policies and rules | F16: 4.2 | G16: Đạt | H16: RULE-01 đến RULE-06.
A17: C04 | B17: C. Yêu cầu vận hành nghiệp vụ | C17: Ràng buộc vận hành | D17: Các ràng buộc ảnh hưởng đến vận hành có được nêu không? | E17: §9.3 Business operational constraints | F17: 4.3 | G17: Đạt
A18: C05 | B18: C. Yêu cầu vận hành nghiệp vụ | C18: Chế độ vận hành | D18: Có mô tả hành vi ở chế độ bình thường, suy giảm, bảo trì không? | E18: §9.3 Business operational modes | F18: 4.4 | G18: Đạt
A19: C06 | B19: C. Yêu cầu vận hành nghiệp vụ | C19: Chất lượng vận hành (NFR) | D19: Các yêu cầu hiệu năng, quy mô, sẵn sàng, khả dụng có ngưỡng đo được không? | E19: §9.3 Business operational quality | F19: 4.5 | G19: Một phần | H19: Có ngưỡng nhưng chưa được IT xác nhận. | I19: IT xác nhận NFR-01 đến NFR-09.
A20: C07 | B20: C. Yêu cầu vận hành nghiệp vụ | C20: Tính liên tục kinh doanh | D20: Có xác định RTO (thời gian khôi phục) và RPO (lượng dữ liệu chấp nhận mất) không? | E20: §9.3 Business operational quality | F20: 4.5 | G20: Một phần | H20: Đã thêm NFR-10 đến NFR-12 (RTO ≤ 4 giờ, RPO ≤ 1 giờ); ngưỡng chưa được IT xác nhận. | I20: IT xác nhận RTO/RPO.
A21: C08 | B21: C. Yêu cầu vận hành nghiệp vụ | C21: Cơ cấu tổ chức và vai trò | D21: Các vai trò, đơn vị và quyền chính có được xác định không? | E21: §9.3 Business structure | F21: 4.6 | G21: Đạt
A22: C09 | B22: C. Yêu cầu vận hành nghiệp vụ | C22: Đặc điểm người dùng | D22: Có mô tả bối cảnh làm việc, tần suất sử dụng và trình độ của từng nhóm người dùng không? | E22: §9.3 Business structure; checklist gốc | F22: 4.6 | G22: Một phần | H22: Đã thêm bảng đặc điểm người dùng; chưa xác nhận qua phỏng vấn. | I22: Phỏng vấn 1–2 người cho mỗi vai trò.
A23: D01 | B23: D. Khái niệm vận hành và vòng đời | C23: Khái niệm vận hành sơ bộ | D23: Có mô tả cách hệ thống được dùng ở mức tổng thể không? | E23: §9.3 Preliminary operational concept | F23: 5.1 | G23: Đạt
A24: D02 | B24: D. Khái niệm vận hành và vòng đời | C24: Kịch bản vận hành | D24: Có kịch bản từ góc nhìn người dùng, mỗi kịch bản truy vết về yêu cầu không? | E24: §9.3 Operational scenarios | F24: 5.2 | G24: Đạt | H24: SC-01 đến SC-04.
A25: D03 | B25: D. Khái niệm vận hành và vòng đời | C25: Khái niệm mua sắm | D25: Đã xác định phương án tự phát triển hay mua không? | E25: §9.3 Other life-cycle concepts – acquisition | F25: 6.1 | G25: Một phần | H25: Chưa chốt (OQ-02). | I25: Sponsor và IT quyết định OQ-02.
A26: D04 | B26: D. Khái niệm vận hành và vòng đời | C26: Khái niệm triển khai | D26: Có kế hoạch thí điểm, mở rộng, đào tạo không? | E26: §9.3 Other life-cycle concepts – deployment | F26: 6.2 | G26: Đạt
A27: D05 | B27: D. Khái niệm vận hành và vòng đời | C27: Khái niệm hỗ trợ | D27: Có mô hình hỗ trợ và giám sát vận hành không? | E27: §9.3 Other life-cycle concepts – support | F27: 6.3 | G27: Đạt
A28: D06 | B28: D. Khái niệm vận hành và vòng đời | C28: Khái niệm thu hồi | D28: Có xử lý dữ liệu và hệ thống khi ngừng sử dụng không? | E28: §9.3 Other life-cycle concepts – retirement | F28: 6.4 | G28: Đạt
A29: E01 | B29: E. Ràng buộc, giả định, phụ thuộc, rủi ro | C29: Ràng buộc dự án | D29: Ngân sách, thời gian, nhân lực có được xác định không? | E29: §9.3 Project constraints | F29: 7 | G29: Một phần | H29: Ngân sách, nhân lực còn "cần xác định". | I29: Sponsor cung cấp ngân sách và mốc thời gian.
A30: E02 | B30: E. Ràng buộc, giả định, phụ thuộc, rủi ro | C30: Giả định | D30: Các giả định quan trọng có được nêu và đánh mã không? | E30: §9.3 Project constraints | F30: 7 | G30: Đạt | H30: A-01 đến A-03.
A31: E03 | B31: E. Ràng buộc, giả định, phụ thuộc, rủi ro | C31: Phụ thuộc | D31: Có liệt kê phụ thuộc vào hệ thống, dịch vụ, nhà cung cấp bên ngoài không? | E31: §9.3 Project constraints | F31: 7 | G31: Đạt | H31: Đã khôi phục: D-01 đến D-05.
A32: E04 | B32: E. Ràng buộc, giả định, phụ thuộc, rủi ro | C32: Rủi ro và giảm thiểu | D32: Rủi ro có đánh giá khả năng, ảnh hưởng và biện pháp giảm thiểu không? | E32: §9.3 Project constraints | F32: 7 | G32: Đạt | H32: R-01 đến R-05.
A33: E05 | B33: E. Ràng buộc, giả định, phụ thuộc, rủi ro | C33: Kế hoạch dự phòng | D33: Rủi ro lớn có kế hoạch dự phòng khi xảy ra không? | E33: Checklist gốc | F33: 7 | G33: Đạt | H33: Có cột Kế hoạch dự phòng cho R-01 đến R-05.
A34: E06 | B34: E. Ràng buộc, giả định, phụ thuộc, rủi ro | C34: Câu hỏi mở | D34: Câu hỏi mở có người trả lời và hạn trả lời không? | E34: Thực hành tốt | F34: 7 | G34: Đạt | H34: Có người trả lời, hạn theo mốc dự án và trạng thái.
A35: F01 | B35: F. Đặc tính từng yêu cầu | C35: Cần thiết (Necessary) | D35: Mỗi yêu cầu có phục vụ ít nhất một mục tiêu; bỏ đi có làm thiếu năng lực không? | E35: §5.2.5 Necessary | F35: 4.1, 8.2 | G35: Đạt | H35: Mọi BR đều truy vết về BO.
A36: F02 | B36: F. Đặc tính từng yêu cầu | C36: Phù hợp mức trừu tượng (Appropriate) | D36: Yêu cầu có ở mức nghiệp vụ, không ràng vào giải pháp kỹ thuật không? | E36: §5.2.5 Appropriate | F36: 4.1 | G36: Đạt | H36: Đã bỏ tên trình duyệt, MP4, H.264/H.265 khỏi BR; chi tiết chuyển xuống PRD/SRS.
A37: F03 | B37: F. Đặc tính từng yêu cầu | C37: Không mơ hồ (Unambiguous) | D37: Mỗi yêu cầu chỉ có một cách hiểu không? | E37: §5.2.5 Unambiguous | F37: 4.1 | G37: Đạt | H37: BR-10 định lượng theo bitrate; BR-27 nêu rõ nội dung thông báo.
A38: F04 | B38: F. Đặc tính từng yêu cầu | C38: Đầy đủ (Complete) | D38: Mỗi yêu cầu có đủ thông tin để hiểu và thực hiện không? | E38: §5.2.5 Complete | F38: 4.1 | G38: Đạt
A39: F05 | B39: F. Đặc tính từng yêu cầu | C39: Đơn nhất (Singular) | D39: Mỗi yêu cầu chỉ nêu một năng lực, không gộp nhiều ý bằng "và"? | E39: §5.2.5 Singular | F39: 4.1 | G39: Đạt | H39: Đã tách BR-09/34, BR-11/35, BR-28/36, BR-31/37, BR-33/38; phần ghi nhật ký của BR-18 do BR-30 đảm nhiệm.
A40: F06 | B40: F. Đặc tính từng yêu cầu | C40: Khả thi (Feasible) | D40: Yêu cầu có thực hiện được trong ràng buộc đã biết không? | E40: §5.2.5 Feasible | F40: 4.1, 7 | G40: Một phần | H40: BR-06, BR-27 phụ thuộc mức hỗ trợ của từng hãng (R-01). | I40: Kiểm tra khả thi với danh sách camera mục tiêu.
...
